Workbook

Sheet Dados gerais
B2: Tratamentos | C2: Geotextil | D2: Tempos (dias) | E2: Repetição | F2: Extensão em Máximo Carga (mm) | G2: Comprimento útil da fibra (mm) | H2: Deformação (ε) | I2: Carga (N) | J2: diametro da fibra (mm) | K2: Resistência à Tração (N/mm)* | L2: Rigidez (Jsec) | M2: Tensão de ruptura | N2: Secante
B3: 0x resina | C3: Ouricuri | D3: 0 | E3: 1 | F3: 7.8751 | G3: 190 | H3: =(F3/G3) -> 0.041447895 | I3: 14.730983 | J3: 3 | K3: =(I3/J3) -> 4.9103277 | L3: =(K3/H3) -> 118.46989 | M3: =I3/(0.785*(J3*J3)) -> 2.0850648 | N3: =K3/H3 -> 118.46989
B4: 0x resina | C4: Ouricuri | D4: 0 | E4: 2 | F4: 7.97491 | G4: 190 | H4: =(F4/G4) -> 0.041973211 | I4: 12.25761 | J4: 3 | K4: =(I4/J4) -> 4.08587 | L4: =(K4/H4) -> 97.34471 | M4: =I4/(0.785*(J4*J4)) -> 1.7349766 | N4: =K4/H4 -> 97.34471
B5: 0x resina | C5: Ouricuri | D5: 0 | E5: 3 | F5: 5.62505 | G5: 190 | H5: =(F5/G5) -> 0.029605526 | I5: 6.453287 | J5: 3 | K5: =(I5/J5) -> 2.1510957 | L5: =(K5/H5) -> 72.658586 | M5: =I5/(0.785*(J5*J5)) -> 0.91341642 | N5: =K5/H5 -> 72.658586
B6: 0x resina | C6: Ouricuri | D6: 0 | E6: 4 | F6: 5.90003 | G6: 190 | H6: =(F6/G6) -> 0.031052789 | I6: 6.727937 | J6: 3 | K6: =(I6/J6) -> 2.2426457 | L6: =(K6/H6) -> 72.220425 | M6: =I6/(0.785*(J6*J6)) -> 0.95229115 | N6: =K6/H6 -> 72.220425
B7: 0x resina | C7: Ouricuri | D7: 0 | E7: 5 | F7: 4.25003 | G7: 190 | H7: =(F7/G7) -> 0.022368579 | I7: 6.993791 | J7: 3 | K7: =(I7/J7) -> 2.3312637 | L7: =(K7/H7) -> 104.22046 | M7: =I7/(0.785*(J7*J7)) -> 0.98992088 | N7: =K7/H7 -> 104.22046
B8: 0x resina | C8: Ouricuri | D8: 30 | E8: 1 | F8: 2.72507 | G8: 190 | H8: =(F8/G8) -> 0.014342474 | I8: 1.95225 | J8: 3 | K8: =(I8/J8) -> 0.65075 | L8: =(K8/H8) -> 45.372229 | M8: =I8/(0.785*(J8*J8)) -> 0.27632696 | N8: =K8/H8 -> 45.372229
B9: 0x resina | C9: Ouricuri | D9: 30 | E9: 2 | F9: 5.57496 | G9: 190 | H9: =(F9/G9) -> 0.029341895 | I9: 1.94602 | J9: 3 | K9: =(I9/J9) -> 0.64867333 | L9: =(K9/H9) -> 22.107411 | M9: =I9/(0.785*(J9*J9)) -> 0.27544515 | N9: =K9/H9 -> 22.107411
B10: 0x resina | C10: Ouricuri | D10: 30 | E10: 3 | F10: 4.42505 | G10: 190 | H10: =(F10/G10) -> 0.023289737 | I10: 0.82677 | J10: 3 | K10: =(I10/J10) -> 0.27559 | L10: =(K10/H10) -> 11.833109 | M10: =I10/(0.785*(J10*J10)) -> 0.11702335 | N10: =K10/H10 -> 11.833109
B11: 0x resina | C11: Ouricuri | D11: 30 | E11: 4 | F11: 6.47507 | G11: 190 | H11: =(F11/G11) -> 0.034079316 | I11: 5.72738 | J11: 3 | K11: =(I11/J11) -> 1.9091267 | L11: =(K11/H11) -> 56.0201 | M11: =I11/(0.785*(J11*J11)) -> 0.8106695 | N11: =K11/H11 -> 56.0201
B12: 0x resina | C12: Ouricuri | D12: 30 | E12: 5 | F12: 6.225 | G12: 190 | H12: =(F12/G12) -> 0.032763158 | I12: 6.85877 | J12: 3 | K12: =(I12/J12) -> 2.2862567 | L12: =(K12/H12) -> 69.781328 | M12: =I12/(0.785*(J12*J12)) -> 0.97080962 | N12: =K12/H12 -> 69.781328
B13: 0x resina | C13: Ouricuri | D13: 30 | E13: 6 | F13: 1.35005 | G13: 190 | H13: =(F13/G13) -> 0.0071055263 | I13: 4.27809 | J13: 3 | K13: =(I13/J13) -> 1.42603 | L13: =(K13/H13) -> 200.69309 | M13: =I13/(0.785*(J13*J13)) -> 0.60553291 | N13: =K13/H13 -> 200.69309
B14: 0x resina | C14: Ouricuri | D14: 30 | E14: 7 | F14: 8.92499 | G14: 190 | H14: =(F14/G14) -> 0.046973632 | I14: 11.23996 | J14: 3 | K14: =(I14/J14) -> 3.7466533 | L14: =(K14/H14) -> 79.760777 | M14: =I14/(0.785*(J14*J14)) -> 1.5909356 | N14: =K14/H14 -> 79.760777
... B79: 2x resina | C79: Ouricuri | D79: 90 | E79: 7 | F79: 0.45 | G79: 190 | H79: =(F79/G79) -> 0.0023684211 | I79: 13.26369 | J79: 3 | K79: =(I79/J79) -> 4.42123 | L79: =(K79/H79) -> 1866.7416 | M79: =I79/(0.785*(J79*J79)) -> 1.87738 | N79: =K79/H79 -> 1866.7416

Sheet Deformação
B2: Tratamentos | C2: Geotextil | D2: Tempos | E2: Deformação
B3: sem resina | C3: Ouricuri | D3: 30 | E3: 4.1447895
B4: sem resina | C4: Ouricuri | D4: 30 | E4: 4.1973211
B5: sem resina | C5: Ouricuri | D5: 30 | E5: 2.9605526
B6: sem resina | C6: Ouricuri | D6: 30 | E6: 3.1052789
B7: sem resina | C7: Ouricuri | D7: 30 | E7: 2.2368579
B8: sem resina | C8: Ouricuri | D8: 60 | E8: 1.4342474
B9: sem resina | C9: Ouricuri | D9: 60 | E9: 2.9341895
B10: sem resina | C10: Ouricuri | D10: 60 | E10: 2.3289737
B11: sem resina | C11: Ouricuri | D11: 60 | E11: 3.4079316
B12: sem resina | C12: Ouricuri | D12: 60 | E12: 3.2763158
B13: sem resina | C13: Ouricuri | D13: 60 | E13: 0.71055263
B14: sem resina | C14: Ouricuri | D14: 60 | E14: 4.6973632
... B99: 2x resina | C99: Ouricuri | D99: 180 | E99: 0

Sheet Gráfico deformação
B2: Ouricuri
B3: Aplicação | C3: Período | D3: Deformação média | T3: Comparações por Método Pairwise
B4: Sem resina | C4: 0 dias | D4: =AVERAGE(Deformação!E3:E7)/100 -> 0.0332896 | T4: Variável dependente: | U4: Deformação
B5: Sem resina | C5: 30 dias | D5: =AVERAGE(Deformação!E8:E14)/100 -> 0.026842248 | T5: Tratamentos | W5: Diferença média (I-J) | X5: Sig.d | Y5: 95% Intervalo de Confiança para Diferençad
B6: Sem resina | C6: 60 dias | D6: =AVERAGE(Deformação!E15:E20)/100 -> 0.014912351 | Y6: Limite inferior | Z6: Limite superior
B7: 1x camada | C7: 0 dias | D7: =AVERAGE(Deformação!E21:E25)/100 -> 0.038947316 | T7: Sem resina | U7: 30 dias | V7: 60 dias | W7: 0.64473519 | X7: 0.97020056 | Y7: -0.94758771 | Z7: 2.2370581
B8: 1x resina | C8: 30 dias | D8: =AVERAGE(Deformação!E26:E32)/100 -> 0.027744429 | V8: 90 dias | W8: 1,838* | X8: 0.023599354 | Y8: 0.19104095 | Z8: 3.4844089
B9: 1x resina | C9: 60 dias | D9: =AVERAGE(Deformação!E33:E39)/100 -> 0.015526316
B10: 1x resina | C10: 90 dias | D10: =AVERAGE(Deformação!E40:E46)/100 -> 0.0064849474
B11: 1x resina | C11: 120 dias | D11: =AVERAGE(Deformação!E47:E53)/100 -> 0.0052255865
B12: 2x camadas | C12: 0 dias | D12: =AVERAGE(Deformação!E60:E64)/100 -> 0.027526389 | U12: 60 dias | V12: 30 dias | W12: -0.64473519 | X12: 0.97020056 | Y12: -2.2370581 | Z12: 0.94758771
B13: 2x resina | C13: 30 dias | D13: =AVERAGE(Deformação!E65:E71)/100 -> 0.020319624 | V13: 90 dias | W13: 1.1929897 | X13: 0.17097816 | Y13: -0.31994981 | Z13: 2.7059293
B14: 2x resina | C14: 60 dias | D14: =AVERAGE(Deformação!E72:E78)/100 -> 0.0099813083 | V14: 120 dias | W14: .b
B15: 2x resina | C15: 90 dias | D15: =AVERAGE(Deformação!E79:E85)/100 -> 0.0042858421 | V15: 150 dias | W15: .b
U16: 90 dias | V16: 30 dias | W16: -1,838* | X16: 0.023599354 | Y16: -3.4844089 | Z16: -0.19104095
V17: 60 dias | W17: -1.1929897 | X17: 0.17097816 | Y17: -2.7059293 | Z17: 0.31994981
T28: 1x Resina | U28: 30 dias | V28: 60 dias | W28: 1.1202887 | X28: 0.8855629 | Y28: -0.76263552 | Z28: 3.003213
V29: 90 dias | W29: 2,342* | X29: 0.0058723747 | Y29: 0.45917576 | Z29: 4.2250242
V30: 120 dias | W30: 3,246* | X30: 4.4346907e-05 | Y30: 1.3633126 | Z30: 5.1291611
V31: 150 dias | W31: 3,372* | X31: 2.130531e-05 | Y31: 1.4892487 | Z31: 5.2550972
U32: 60 dias | V32: 30 dias | W32: -1.1202887 | X32: 0.8855629 | Y32: -3.003213 | Z32: 0.76263552
V33: 90 dias | W33: 1.2218113 | X33: 0.42851275 | Y33: -0.49705552 | Z33: 2.9406781
V34: 120 dias | W34: 2,126* | X34: 0.0062697126 | Y34: 0.40708132 | Z34: 3.8448149
V35: 150 dias | W35: 2,252* | X35: 0.0031383374 | Y35: 0.53301741 | Z35: 3.970751
U36: 90 dias | V36: 30 dias | W36: -2,342* | X36: 0.0058723747 | Y36: -4.2250242 | Z36: -0.45917576
V37: 60 dias | W37: -1.2218113 | X37: 0.42851275 | Y37: -2.9406781 | Z37: 0.49705552
V38: 120 dias | W38: 0.90413684 | X38: 1 | Y38: -0.81472996 | Z38: 2.6230036
V39: 150 dias | W39: 1.0300729 | X39: 0.86326753 | Y39: -0.68879387 | Z39: 2.7489397
U40: 120 dias | V40: 30 dias | W40: -3,246* | X40: 4.4346907e-05 | Y40: -5.1291611 | Z40: -1.3633126
V41: 60 dias | W41: -2,126* | X41: 0.0062697126 | Y41: -3.8448149 | Z41: -0.40708132
V42: 90 dias | W42: -0.90413684 | X42: 1 | Y42: -2.6230036 | Z42: 0.81472996
V43: 150 dias | W43: 0.12593609 | X43: 1 | Y43: -1.5929307 | Z43: 1.8448029
U44: 150 dias | V44: 30 dias | W44: -3,372* | X44: 2.130531e-05 | Y44: -5.2550972 | Z44: -1.4892487
V45: 60 dias | W45: -2,252* | X45: 0.0031383374 | Y45: -3.970751 | Z45: -0.53301741
V46: 90 dias | W46: -1.0300729 | X46: 0.86326753 | Y46: -2.7489397 | Z46: 0.68879387
V47: 120 dias | W47: -0.12593609 | X47: 1 | Y47: -1.8448029 | Z47: 1.5929307
T48: 2x Resina | U48: 30 dias | V48: 60 dias | W48: 0.72067654 | X48: 1 | Y48: -1.0426306 | Z48: 2.4839836
V49: 90 dias | W49: 1.7545081 | X49: 0.051871614 | Y49: -0.0087989713 | Z49: 3.5178152
V50: 120 dias | W50: 2,324* | X50: 0.0038520766 | Y50: 0.56074765 | Z50: 4.0873618
V51: 150 dias | W51: .b
...

Sheet Planilha3
A1: Para converter esses valores em porcentagem, basta multiplicá-los por 100. Segue o resultado para os pares de valores fornecidos:
A3: Valor 1 | B3: Valor 2 | C3: Percentagem 1 (%) | D3: Percentagem 2 (%)
A4: -0.019 | B4: 0.032 | C4: -1.9% | D4: 3.2%
A5: -0.016 | B5: 0.035 | C5: -1.6% | D5: 3.5%
A6: -0.021 | B6: 0.034 | C6: -2.1% | D6: 3.4%
A7: 0.001 | B7: 0.037 | C7: 0.1% | D7: 3.7%
A8: 0.004 | B8: 0.040 | C8: 0.4% | D8: 4.0%
A9: -0.001 | B9: 0.038 | C9: -0.1% | D9: 3.8%
A10: - | B10: - | C10: - | D10: -
A11: 0.021 | B11: 0.045 | C11: 2.1% | D11: 4.5%
A12: 0.011 | B12: 0.037 | C12: 1.1% | D12: 3.7%
A13: - | B13: - | C13: - | D13: -
A14: 0.023 | B14: 0.044 | C14: 2.3% | D14: 4.4%
A16: Se precisar de mais alguma análise ou ajustes, é só avisar!

Sheet Gráfico secante
V1: Post Hoc Tests
B2: Ouricuri
B3: Aplicação | C3: Período | D3: Deformação | V3: Post Hoc Comparisons - Tratamentos ✻ RM Factor 1
B4: Sem resina | C4: 00 dias | D4: =AVERAGE('Dados gerais'!N3:N7) -> 92.982816 | E4: =D4/100 -> 0.92982816 | AA4: 95% CI for Mean Difference | AF4: Comparações por Método Pairwise
B5: Sem resina | C5: 30 dias | D5: =AVERAGE('Dados gerais'!N8:N12) -> 41.022835 | E5: =D5/100 -> 0.41022835 | Y5: Mean Difference | AA5: Lower | AB5: Upper | AC5: Cohen's d | AD5: pbonf | AF5: Variável dependente: | AG5: secante
B6: Sem resina | C6: 60 dias | D6: =AVERAGE('Dados gerais'!N8:N14) -> 69.366863 | E6: =D6/100 -> 0.69366863 | V6: Sem, resina, T1 | X6: 1x, resina, T1 | Y6: 4.219e-12 | AA6: -4592 | AB6: 4592 | AC6: 1.776e-12 | AD6: 1000 | AF6: Tratamentos | AI6: Diferença média (I-J) | AJ6: Sig.d | AK6: 95% Intervalo de Confiança para Diferençad
B7: 1x resin | C7: 0 dias | D7: =AVERAGE('Dados gerais'!N21:N25) -> 143.7003 | E7: =D7/100 -> 1.437003 | X7: 2x, resina, T2 | Y7: 2296 | AA7: -2297 | AB7: 6888 | AC7: 1011 | AD7: 1000 | AK7: Limite inferior | AL7: Limite superior
B8: 1x resina | C8: 30 dias | D8: =AVERAGE('Dados gerais'!N26:N32) -> 191.56701 | E8: =D8/100 -> 1.9156701 | X8: Sem, resina, T3 | Y8: 7753 | AA8: 3232 | AB8: 12274 | AC8: 3415 | AD8: < .001 | AE8: *** | AF8: Sem resina | AG8: 30 dias | AH8: 60 dias | AI8: 8.6046129 | AJ8: 0.088084939 | AK8: -0.8872811 | AL8: 18.096507
B9: 1x resina | C9: 60 dias | D9: =AVERAGE('Dados gerais'!N33:N39) -> 105.47429 | E9: =D9/100 -> 1.0547429 | X9: 1x, resina, T3 | Y9: 8738 | AA9: 4146 | AB9: 13331 | AC9: 3849 | AD9: < .001 | AE9: *** | AH9: 90 dias | AI9: 8.3423814 | AJ9: 0.12199562 | AK9: -1.4735608 | AL9: 18.158324
B10: 1x resina | C10: 90 dias | D10: =AVERAGE('Dados gerais'!N40:N47) -> 396.51325 | E10: =D10/100 -> 3.9651325
B11: 1x resina | C11: 120 dias | D11: =AVERAGE('Dados gerais'!N47:N53) -> 268.54824 | E11: =D11/100 -> 2.6854824 | X11: 2x, resina, T3 | Y11: 8893 | AA11: 4301 | AB11: 13486 | AC11: 3917 | AD11: < .001 | AE11: ***
B12: 2x resin | C12: 0 dias | D12: =AVERAGE('Dados gerais'!N54:N58) -> 191.26107 | E12: =D12/100 -> 1.9126107 | X12: 2x, resina, T4 | Y12: 5635 | AA12: 1043 | AB12: 10228 | AC12: 2482 | AD12: 0.002 | AE12: **
B13: 2x resina | C13: 30 dias | D13: =AVERAGE('Dados gerais'!N59:N64) -> 495.95866 | E13: =D13/100 -> 4.9595866 | X13: Sem, resina, T5 | Y13: 4470 | AA13: -0.052 | AB13: 8991 | AC13: 1969 | AD13: 0.058 | AG13: 60 dias | AH13: 30 dias | AI13: -8.6046129 | AJ13: 0.088084939 | AK13: -18.096507 | AL13: 0.8872811
B14: 2x resina | C14: 60 dias | D14: =AVERAGE('Dados gerais'!N66:N72) -> 263.6734 | E14: =D14/100 -> 2.636734 | X14: 1x, resina, T5 | Y14: 6292 | AA14: 1700 | AB14: 10885 | AC14: 2771 | AD14: < .001 | AE14: *** | AH14: 90 dias | AI14: -0.26223148 | AJ14: 1 | AK14: -9.2809184 | AL14: 8.7564554
B15: 2x resina | C15: 90 dias | D15: =AVERAGE('Dados gerais'!N73:N79) -> 556.34316 | E15: =D15/100 -> 5.5634316 | X15: 2x, resina, T5 | Y15: 6154 | AA15: 1562 | AB15: 10747 | AC15: 2711 | AD15: < .001 | AE15: *** | AH15: 120 dias | AI15: .a
X16: 2x, resina, T6 | Y16: 6653 | AA16: 2060 | AB16: 11245 | AC16: 2930 | AD16: < .001 | AE16: *** | AH16: 150 dias | AI16: .a
X17: Sem, resina, T7 | Y17: 7333 | AA17: 2812 | AB17: 11854 | AC17: 3230 | AD17: < .001 | AE17: *** | AG17: 90 dias | AH17: 30 dias | AI17: -8.3423814 | AJ17: 0.12199562 | AK17: -18.158324 | AL17: 1.4735608
X18: 1x, resina, T7 | Y18: 7669 | AA18: 3076 | AB18: 12261 | AC18: 3378 | AD18: < .001 | AE18: *** | AH18: 60 dias | AI18: 0.26223148 | AJ18: 1 | AK18: -8.7564554 | AL18: 9.2809184
X19: 2x, resina, T7 | Y19: 9856 | AA19: 5264 | AB19: 14449 | AC19: 4341 | AD19: < .001 | AE19: ***
V20: 1x, resina, T1 | X20: 2x, resina, T1 | Y20: 3.553e-12 | AA20: -4592 | AB20: 4592 | AC20: 2.665e-12 | AD20: 1000
X21: Sem, resina, T2 | Y21: 4271 | AA21: -0.321 | AB21: 8864 | AC21: 1881 | AD21: 0.127 | AG21: 120 dias
X22: 1x, resina, T2 | Y22: 3490 | AA22: -1032 | AB22: 8011 | AC22: 1537 | AD22: 0.857
X23: 2x, resina, T2 | Y23: 2296 | AA23: -2297 | AB23: 6888 | AC23: 1011 | AD23: 1000
X24: Sem, resina, T3 | Y24: 7753 | AA24: 3161 | AB24: 12346 | AC24: 3415 | AD24: < .001 | AE24: ***
X25: 1x, resina, T3 | Y25: 8738 | AA25: 4217 | AB25: 13259 | AC25: 3849 | AD25: < .001 | AE25: *** | AG25: 150 dias
X26: 2x, resina, T3 | Y26: 8893 | AA26: 4301 | AB26: 13486 | AC26: 3917 | AD26: < .001 | AE26: ***
X27: Sem, resina, T4 | Y27: 5577 | AA27: 0.984 | AB27: 10169 | AC27: 2456 | AD27: 0.002 | AE27: **
X28: 1x, resina, T4 | Y28: 6539 | AA28: 2017 | AB28: 11060 | AC28: 2880 | AD28: < .001 | AE28: ***
X29: 2x, resina, T4 | Y29: 5635 | AA29: 1043 | AB29: 10228 | AC29: 2482 | AD29: 0.002 | AE29: ** | AF29: 1x Resina | AG29: 30 dias | AH29: 60 dias | AI29: 10.107551 | AJ29: 0.11023678 | AK29: -1.1166278 | AL29: 21.33173
W30: Sem, resina, T5 | X30: 4470 | Z30: -0.123 | AA30: 9062 | AB30: 1969 | AC30: 0.072 | AH30: 90 dias | AI30: 13,315* | AJ30: 0.0099744517 | AK30: 2.0911076 | AL30: 24.539466
W31: 1x, resina, T5 | X31: 6292 | Z31: 1771 | AA31: 10813 | AB31: 2771 | AC31: < .001 | AD31: *** | AH31: 120 dias | AI31: 10.23595 | AJ31: 0.1009238 | AK31: -0.98822879 | AL31: 21.460129
W32: 2x, resina, T5 | X32: 6154 | Z32: 1562 | AA32: 10747 | AB32: 2711 | AC32: < .001 | AD32: *** | AH32: 150 dias | AI32: 11,685* | AJ32: 0.035564552 | AK32: 0.46036806 | AL32: 22.908726
W33: Sem, resina, T6 | X33: 4470 | Z33: -0.123 | AA33: 9062 | AB33: 1969 | AC33: 0.072 | AG33: 60 dias | AH33: 30 dias | AI33: -10.107551 | AJ33: 0.11023678 | AK33: -21.33173 | AL33: 1.1166278
W34: 1x, resina, T6 | X34: 7763 | Z34: 3241 | AA34: 12284 | AB34: 3419 | AC34: < .001 | AD34: *** | AH34: 90 dias | AI34: 3.2077354 | AJ34: 1 | AK34: -7.0384914 | AL34: 13.453962
W35: 2x, resina, T6 | X35: 6653 | Z35: 2060 | AA35: 11245 | AB35: 2930 | AC35: < .001 | AD35: *** | AH35: 120 dias | AI35: 0.12839901 | AJ35: 1 | AK35: -10.117828 | AL35: 10.374626
W36: Sem, resina, T7 | X36: 7333 | Z36: 2741 | AA36: 11926 | AB36: 3230 | AC36: < .001 | AD36: *** | AH36: 150 dias | AI36: 1.5769959 | AJ36: 1 | AK36: -8.6692309 | AL36: 11.823223
W37: 1x, resina, T7 | X37: 7669 | Z37: 3148 | AA37: 12190 | AB37: 3378 | AC37: < .001 | AD37: *** | AG37: 90 dias | AH37: 30 dias | AI37: -13,315* | AJ37: 0.0099744517 | AK37: -24.539466 | AL37: -2.0911076
W38: 2x, resina, T7 | X38: 9856 | Z38: 5264 | AA38: 14449 | AB38: 4341 | AC38: < .001 | AD38: *** | AH38: 60 dias | AI38: -3.2077354 | AJ38: 1 | AK38: -13.453962 | AL38: 7.0384914
U39: 2x, resina, T1 | W39: Sem, resina, T2 | X39: 4271 | Z39: -0.321 | AA39: 8864 | AB39: 1881 | AC39: 0.127 | AH39: 120 dias | AI39: -3.0793364 | AJ39: 1 | AK39: -13.325563 | AL39: 7.1668904
W40: 1x, resina, T2 | X40: 3490 | Z40: -1103 | AA40: 8082 | AB40: 1537 | AC40: 0.996 | AH40: 150 dias | AI40: -1.6307395 | AJ40: 1 | AK40: -11.876966 | AL40: 8.6154872
...

Sheet resistencia a tração
U1: Post Hoc Tests
B2: Ouricuri
B3: Aplicação | C3: Período | D3: Tração | U3: Post Hoc Comparisons - Tratamentos ✻ RM Factor 1
B4: Sem resina | C4: 0 | D4: =AVERAGE('Dados gerais'!K3:K7) -> 3.1442405 | Z4: 95% CI for Mean Difference | AE4: Comparações por Método Pairwise
B5: Sem resina | C5: 1 | D5: =AVERAGE('Dados gerais'!K8:K14) -> 1.5632971 | X5: Mean Difference | Z5: Lower | AA5: Upper | AB5: Cohen's d | AC5: pbonf | AE5: Variável dependente: | AF5: secante
B6: Sem resina | C6: 2 | D6: =AVERAGE('Dados gerais'!K15:K20) -> 1.2706828 | U6: Sem, resina, T1 | W6: 1x, resina, T1 | X6: 4.219e-12 | Z6: -4592 | AA6: 4592 | AB6: 1.776e-12 | AC6: 1000 | AE6: Tratamentos | AH6: Diferença média (I-J) | AI6: Sig.d | AJ6: 95% Intervalo de Confiança para Diferençad
B7: 1x resin | C7: 0 | D7: =AVERAGE('Dados gerais'!K21:K25) -> 5.4809698 | W7: 2x, resina, T2 | X7: 2296 | Z7: -2297 | AA7: 6888 | AB7: 1011 | AC7: 1000 | AJ7: Limite inferior | AK7: Limite superior
B8: 1x resina | C8: 1 | D8: =AVERAGE('Dados gerais'!K26:K32) -> 3.6961848 | W8: Sem, resina, T3 | X8: 7753 | Z8: 3232 | AA8: 12274 | AB8: 3415 | AC8: < .001 | AD8: *** | AE8: Sem resina | AF8: 30 dias | AG8: 60 dias | AH8: 8.6046129 | AI8: 0.088084939 | AJ8: -0.8872811 | AK8: 18.096507
B9: 1x resina | C9: 2 | D9: =AVERAGE('Dados gerais'!K33:K39) -> 1.3895238 | W9: 1x, resina, T3 | X9: 8738 | Z9: 4146 | AA9: 13331 | AB9: 3849 | AC9: < .001 | AD9: *** | AG9: 90 dias | AH9: 8.3423814 | AI9: 0.12199562 | AJ9: -1.4735608 | AK9: 18.158324
B10: 1x resina | C10: 3 | D10: =AVERAGE('Dados gerais'!K40:K46) -> 1.3603686
B11: 1x resina | C11: 4 | D11: =AVERAGE('Dados gerais'!K47:K53) -> 0.96438905 | W11: 2x, resina, T3 | X11: 8893 | Z11: 4301 | AA11: 13486 | AB11: 3917 | AC11: < .001 | AD11: ***
B12: 2x resin | C12: 0 | D12: =AVERAGE('Dados gerais'!K59:K65) -> 5.7612511 | W12: 2x, resina, T4 | X12: 5635 | Z12: 1043 | AA12: 10228 | AB12: 2482 | AC12: 0.002 | AD12: **
B13: 2x resina | C13: 1 | D13: =AVERAGE('Dados gerais'!K66:K72) -> 1.9770795 | W13: Sem, resina, T5 | X13: 4470 | Z13: -0.052 | AA13: 8991 | AB13: 1969 | AC13: 0.058 | AF13: 60 dias | AG13: 30 dias | AH13: -8.6046129 | AI13: 0.088084939 | AJ13: -18.096507 | AK13: 0.8872811
B14: 2x resina | C14: 2 | D14: =AVERAGE('Dados gerais'!K73:K78) -> 1.0694342 | W14: 1x, resina, T5 | X14: 6292 | Z14: 1700 | AA14: 10885 | AB14: 2771 | AC14: < .001 | AD14: *** | AG14: 90 dias | AH14: -0.26223148 | AI14: 1 | AJ14: -9.2809184 | AK14: 8.7564554
B15: 2x resina | C15: 3 | D15: =AVERAGE('Dados gerais'!K73:K79) -> 1.5482622 | W15: 2x, resina, T5 | X15: 6154 | Z15: 1562 | AA15: 10747 | AB15: 2711 | AC15: < .001 | AD15: *** | AG15: 120 dias | AH15: .a
W16: 2x, resina, T6 | X16: 6653 | Z16: 2060 | AA16: 11245 | AB16: 2930 | AC16: < .001 | AD16: *** | AG16: 150 dias | AH16: .a
W17: Sem, resina, T7 | X17: 7333 | Z17: 2812 | AA17: 11854 | AB17: 3230 | AC17: < .001 | AD17: *** | AF17: 90 dias | AG17: 30 dias | AH17: -8.3423814 | AI17: 0.12199562 | AJ17: -18.158324 | AK17: 1.4735608
W18: 1x, resina, T7 | X18: 7669 | Z18: 3076 | AA18: 12261 | AB18: 3378 | AC18: < .001 | AD18: *** | AG18: 60 dias | AH18: 0.26223148 | AI18: 1 | AJ18: -8.7564554 | AK18: 9.2809184
W19: 2x, resina, T7 | X19: 9856 | Z19: 5264 | AA19: 14449 | AB19: 4341 | AC19: < .001 | AD19: ***
U20: 1x, resina, T1 | W20: 2x, resina, T1 | X20: 3.553e-12 | Z20: -4592 | AA20: 4592 | AB20: 2.665e-12 | AC20: 1000
W21: Sem, resina, T2 | X21: 4271 | Z21: -0.321 | AA21: 8864 | AB21: 1881 | AC21: 0.127 | AF21: 120 dias
W22: 1x, resina, T2 | X22: 3490 | Z22: -1032 | AA22: 8011 | AB22: 1537 | AC22: 0.857
W23: 2x, resina, T2 | X23: 2296 | Z23: -2297 | AA23: 6888 | AB23: 1011 | AC23: 1000
W24: Sem, resina, T3 | X24: 7753 | Z24: 3161 | AA24: 12346 | AB24: 3415 | AC24: < .001 | AD24: ***
W25: 1x, resina, T3 | X25: 8738 | Z25: 4217 | AA25: 13259 | AB25: 3849 | AC25: < .001 | AD25: *** | AF25: 150 dias
W26: 2x, resina, T3 | X26: 8893 | Z26: 4301 | AA26: 13486 | AB26: 3917 | AC26: < .001 | AD26: ***
W27: Sem, resina, T4 | X27: 5577 | Z27: 0.984 | AA27: 10169 | AB27: 2456 | AC27: 0.002 | AD27: **
W28: 1x, resina, T4 | X28: 6539 | Z28: 2017 | AA28: 11060 | AB28: 2880 | AC28: < .001 | AD28: ***
W29: 2x, resina, T4 | X29: 5635 | Z29: 1043 | AA29: 10228 | AB29: 2482 | AC29: 0.002 | AD29: ** | AE29: 1x Resina | AF29: 30 dias | AG29: 60 dias | AH29: 10.107551 | AI29: 0.11023678 | AJ29: -1.1166278 | AK29: 21.33173
V30: Sem, resina, T5 | W30: 4470 | Y30: -0.123 | Z30: 9062 | AA30: 1969 | AB30: 0.072 | AG30: 90 dias | AH30: 13,315* | AI30: 0.0099744517 | AJ30: 2.0911076 | AK30: 24.539466
V31: 1x, resina, T5 | W31: 6292 | Y31: 1771 | Z31: 10813 | AA31: 2771 | AB31: < .001 | AC31: *** | AG31: 120 dias | AH31: 10.23595 | AI31: 0.1009238 | AJ31: -0.98822879 | AK31: 21.460129
V32: 2x, resina, T5 | W32: 6154 | Y32: 1562 | Z32: 10747 | AA32: 2711 | AB32: < .001 | AC32: *** | AG32: 150 dias | AH32: 11,685* | AI32: 0.035564552 | AJ32: 0.46036806 | AK32: 22.908726
V33: Sem, resina, T6 | W33: 4470 | Y33: -0.123 | Z33: 9062 | AA33: 1969 | AB33: 0.072 | AF33: 60 dias | AG33: 30 dias | AH33: -10.107551 | AI33: 0.11023678 | AJ33: -21.33173 | AK33: 1.1166278
V34: 1x, resina, T6 | W34: 7763 | Y34: 3241 | Z34: 12284 | AA34: 3419 | AB34: < .001 | AC34: *** | AG34: 90 dias | AH34: 3.2077354 | AI34: 1 | AJ34: -7.0384914 | AK34: 13.453962
V35: 2x, resina, T6 | W35: 6653 | Y35: 2060 | Z35: 11245 | AA35: 2930 | AB35: < .001 | AC35: *** | AG35: 120 dias | AH35: 0.12839901 | AI35: 1 | AJ35: -10.117828 | AK35: 10.374626
V36: Sem, resina, T7 | W36: 7333 | Y36: 2741 | Z36: 11926 | AA36: 3230 | AB36: < .001 | AC36: *** | AG36: 150 dias | AH36: 1.5769959 | AI36: 1 | AJ36: -8.6692309 | AK36: 11.823223
V37: 1x, resina, T7 | W37: 7669 | Y37: 3148 | Z37: 12190 | AA37: 3378 | AB37: < .001 | AC37: *** | AF37: 90 dias | AG37: 30 dias | AH37: -13,315* | AI37: 0.0099744517 | AJ37: -24.539466 | AK37: -2.0911076
V38: 2x, resina, T7 | W38: 9856 | Y38: 5264 | Z38: 14449 | AA38: 4341 | AB38: < .001 | AC38: *** | AG38: 60 dias | AH38: -3.2077354 | AI38: 1 | AJ38: -13.453962 | AK38: 7.0384914
T39: 2x, resina, T1 | V39: Sem, resina, T2 | W39: 4271 | Y39: -0.321 | Z39: 8864 | AA39: 1881 | AB39: 0.127 | AG39: 120 dias | AH39: -3.0793364 | AI39: 1 | AJ39: -13.325563 | AK39: 7.1668904
V40: 1x, resina, T2 | W40: 3490 | Y40: -1103 | Z40: 8082 | AA40: 1537 | AB40: 0.996 | AG40: 150 dias | AH40: -1.6307395 | AI40: 1 | AJ40: -11.876966 | AK40: 8.6154872
...
